Workbook
Name UPDATE: 'Data Sheet'!$E$1

Sheet Data Sheet
A1: COMPANY NAME | B1: INFOSYS LTD | E1: =IF(B2<>B3, "A NEW VERSION OF THE WORKSHEET IS AVAILABLE", "")
A2: LATEST VERSION | B2: 2.1 | E2: PLEASE DO NOT MAKE ANY CHANGES TO THIS SHEET
A3: CURRENT VERSION | B3: 2.1
A5: META
A6: Number of shares | B6: =IF(B9>0, B9/B8, 0) -> 405.46238
A7: Face Value | B7: 5
A8: Current Price | B8: 1161.2
A9: Market Capitalization | B9: 470822.91
A15: PROFIT & LOSS
A16: Report Date | B16: 42825 | C16: 43190 | D16: 43555 | E16: 43921 | F16: 44286 | G16: 44651 | H16: 45016 | I16: 45382 | J16: 45747 | K16: 46112
A17: Sales | B17: 68484 | C17: 70522 | D17: 82675 | E17: 90791 | F17: 100472 | G17: 121641 | H17: 146767 | I17: 153670 | J17: 162990 | K17: 178650
A18: Raw Material Cost
A19: Change in Inventory
A20: Power and Fuel | B20: 228 | C20: 207 | D20: 221 | E20: 229 | F20: 143 | G20: 132 | H20: 176 | I20: 199 | J20: 222 | K20: 223
A21: Other Mfr. Exp | B21: 6712 | C21: 7286 | D21: 9902 | E21: 11086 | F21: 12800 | G21: 20690 | H21: 26330 | I21: 27195 | J21: 30395 | K21: 32922
A22: Employee Cost | B22: 37669 | C22: 38902 | D22: 45323 | E22: 50895 | F22: 55547 | G22: 63997 | H22: 78374 | I22: 82636 | J22: 85968 | K22: 95112
A23: Selling and admin | B23: 4584 | C23: 4585 | D23: 5553 | E23: 5375 | F23: 3194 | G23: 4305 | H23: 5300 | I23: 5705 | J23: 6039 | K23: 6784
A24: Other Expenses | B24: 687 | C24: 720 | D24: 1506 | E24: 939 | F24: 899 | G24: 1026 | H24: 1457 | I24: 1510 | J24: 1130 | K24: 1329
A25: Other Income | B25: 3050 | C25: 3311 | D25: 2882 | E25: 2803 | F25: 2201 | G25: 2295 | H25: 2701 | I25: 4711 | J25: 3600 | K25: 3033
A26: Depreciation | B26: 1703 | C26: 1863 | D26: 2011 | E26: 2893 | F26: 3267 | G26: 3476 | H26: 4225 | I26: 4678 | J26: 4812 | K26: 4902
A27: Interest | E27: 170 | F27: 195 | G27: 200 | H27: 284 | I27: 470 | J27: 416 | K27: 416
A28: Profit before tax | B28: 19951 | C28: 20270 | D28: 21041 | E28: 22007 | F28: 26628 | G28: 30110 | H28: 33322 | I28: 35988 | J28: 37608 | K28: 39995
A29: Tax | B29: 5598 | C29: 4241 | D29: 5631 | E29: 5368 | F29: 7205 | G29: 7964 | H29: 9214 | I29: 9740 | J29: 10858 | K29: 10521
A30: Net profit | B30: 14353 | C30: 16029 | D30: 15404 | E30: 16594 | F30: 19351 | G30: 22110 | H30: 24095 | I30: 26233 | J30: 26713 | K30: 29440
A31: Dividend Amount | B31: 5891.6 | C31: 9465.6 | D31: 9222.5 | E31: 7427 | F31: 11469.6 | G31: 13007.6 | H31: 14069.2 | I31: 19053.2 | J31: 17827.8 | K31: 19430.4
A32: ='Historical Financial Statement'!B10 -> EBITDA | B32: ='Historical Financial Statement'!C10 -> 18604 | C32: ='Historical Financial Statement'!D10 -> 18822 | D32: ='Historical Financial Statement'!E10 -> 20170 | E32: ='Historical Financial Statement'!F10 -> 22267 | F32: ='Historical Financial Statement'!G10 -> 27889 | G32: ='Historical Financial Statement'!H10 -> 31491 | H32: ='Historical Financial Statement'!I10 -> 35130 | ... K32: ='Historical Financial Statement'!L10 -> 42280
A33: ='Historical Financial Statement'!B14 -> EBIT | B33: ='Historical Financial Statement'!C14 -> 16901 | C33: ='Historical Financial Statement'!D14 -> 16959 | D33: ='Historical Financial Statement'!E14 -> 18159 | E33: ='Historical Financial Statement'!F14 -> 19374 | F33: ='Historical Financial Statement'!G14 -> 24622 | G33: ='Historical Financial Statement'!H14 -> 28015 | H33: ='Historical Financial Statement'!I14 -> 30905 | ... K33: ='Historical Financial Statement'!L14 -> 37378
A40: Quarters
A41: Report Date | B41: 45382 | C41: 45473 | D41: 45565 | E41: 45657 | F41: 45747 | G41: 45838 | H41: 45930 | I41: 46022 | J41: 46112 | K41: 46203
A42: Sales | B42: 37923 | C42: 39315 | D42: 40986 | E42: 41764 | F42: 40925 | G42: 42279 | H42: 44490 | I42: 45479 | J42: 46402 | K42: 48211
A43: Expenses | B43: 29139 | C43: 29878 | D43: 31177 | E43: 31649 | F43: 31051 | G43: 32336 | H43: 33955 | I43: 34845 | J43: 35235 | K43: 36802
A44: Other Income | B44: 2729 | C44: 838 | D44: 712 | E44: 859 | F44: 1190 | G44: 1042 | H44: 982 | I44: -150 | J44: 1159 | K44: 984
A45: Depreciation | B45: 1163 | C45: 1149 | D45: 1160 | E45: 1203 | F45: 1299 | G45: 1140 | H45: 1182 | I45: 1155 | J45: 1424 | K45: 1246
A46: Interest | B46: 110 | C46: 105 | D46: 108 | E46: 101 | F46: 102 | G46: 105 | H46: 106 | I46: 100 | J46: 105 | K46: 119
A47: Profit before tax | B47: 10240 | C47: 9021 | D47: 9253 | E47: 9670 | F47: 9663 | G47: 9740 | H47: 10229 | I47: 9229 | J47: 10797 | K47: 11028
A48: Tax | B48: 2265 | C48: 2647 | D48: 2737 | E48: 2848 | F48: 2625 | G48: 2816 | H48: 2854 | I48: 2563 | J48: 2288 | K48: 3253
A49: Net profit | B49: 7969 | C49: 6368 | D49: 6506 | E49: 6806 | F49: 7033 | G49: 6921 | H49: 7364 | I49: 6654 | J49: 8501 | K49: 7769
A50: Operating Profit | B50: 8784 | C50: 9437 | D50: 9809 | E50: 10115 | F50: 9874 | G50: 9943 | H50: 10535 | I50: 10634 | J50: 11167 | K50: 11409
A55: BALANCE SHEET
A56: Report Date | B56: 42825 | C56: 43190 | D56: 43555 | E56: 43921 | F56: 44286 | G56: 44651 | H56: 45016 | I56: 45382 | J56: 45747 | K56: 46112
...

Sheet Historical Financial Statement
A1: * | B1: ="Income Statement for "&'Data Sheet'!B1 -> Income Statement for INFOSYS LTD
B2: ='Data Sheet'!A16 -> Report Date | C2: ='Data Sheet'!B16 -> 42825 | D2: ='Data Sheet'!C16 -> 43190 | E2: ='Data Sheet'!D16 -> 43555 | F2: ='Data Sheet'!E16 -> 43921 | G2: ='Data Sheet'!F16 -> 44286 | H2: ='Data Sheet'!G16 -> 44651 | I2: ='Data Sheet'!H16 -> 45016 | ... L2: ='Data Sheet'!K16 -> 46112 | M2: =L2+365 -> 46477 | N2: =M2+365 -> 46842 | O2: =N2+365 -> 47207 | P2: =O2+365 -> 47572 | Q2: =P2+365 -> 47937
B3: ='Data Sheet'!A17 -> Sales | C3: ='Data Sheet'!B17 -> 68484 | D3: ='Data Sheet'!C17 -> 70522 | E3: ='Data Sheet'!D17 -> 82675 | F3: ='Data Sheet'!E17 -> 90791 | G3: ='Data Sheet'!F17 -> 100472 | H3: ='Data Sheet'!G17 -> 121641 | I3: ='Data Sheet'!H17 -> 146767 | ... L3: ='Data Sheet'!K17 -> 178650 | M3: =Calculation!M3 -> 196627.57 | N3: =Calculation!N3 -> 216414.22 | O3: =Calculation!O3 -> 238192.01 | P3: =Calculation!P3 -> 262161.3 | Q3: =Calculation!Q3 -> 288542.62
B4: COGS | C4: =SUM('Data Sheet'!B20:B22) -> 44609 | D4: =SUM('Data Sheet'!C20:C22) -> 46395 | E4: =SUM('Data Sheet'!D20:D22) -> 55446 | F4: =SUM('Data Sheet'!E20:E22) -> 62210 | G4: =SUM('Data Sheet'!F20:F22) -> 68490 | H4: =SUM('Data Sheet'!G20:G22) -> 84819 | I4: =SUM('Data Sheet'!H20:H22) -> 104880 | J4: =SUM('Data Sheet'!I20:I22) -> 110030 | ... L4: =SUM('Data Sheet'!K20:K22) -> 128257 | M4: =Calculation!M6 -> 135828.55 | N4: =Calculation!N6 -> 150349.94 | O4: =Calculation!O6 -> 166357.47 | P4: =Calculation!P6 -> 183825.99 | Q4: =Calculation!Q6 -> 202785.92
B5: Gross Profit | C5: =C3-C4 -> 23875 | D5: =D3-D4 -> 24127 | E5: =E3-E4 -> 27229 | F5: =F3-F4 -> 28581 | G5: =G3-G4 -> 31982 | H5: =H3-H4 -> 36822 | I5: =I3-I4 -> 41887 | J5: =J3-J4 -> 43640 | ... Q5: =Q3-Q4 -> 85756.699
B6: Gross Profit Margin | C6: =C5/C3 -> 0.34862158 | D6: =D5/D3 -> 0.34212019 | E6: =E5/E3 -> 0.32934986 | F6: =F5/F3 -> 0.31479993 | G6: =G5/G3 -> 0.31831754 | H6: =H5/H3 -> 0.30271043 | I6: =I5/I3 -> 0.28539794 | J6: =J5/J3 -> 0.28398516 | ... Q6: =Q5/Q3 -> 0.29720635
B8: ='Data Sheet'!A23 -> Selling and admin | C8: ='Data Sheet'!B23 -> 4584 | D8: ='Data Sheet'!C23 -> 4585 | E8: ='Data Sheet'!D23 -> 5553 | F8: ='Data Sheet'!E23 -> 5375 | G8: ='Data Sheet'!F23 -> 3194 | H8: ='Data Sheet'!G23 -> 4305 | I8: ='Data Sheet'!H23 -> 5300 | ... L8: ='Data Sheet'!K23 -> 6784 | M8: =Calculation!M10 -> 9315.4617 | N8: =Calculation!N10 -> 9829.5894 | O8: =Calculation!O10 -> 10352.007 | P8: =Calculation!P10 -> 10772.255 | Q8: =Calculation!Q10 -> 11333.667
B9: ='Data Sheet'!A24 -> Other Expenses | C9: ='Data Sheet'!B24 -> 687 | D9: ='Data Sheet'!C24 -> 720 | E9: ='Data Sheet'!D24 -> 1506 | F9: ='Data Sheet'!E24 -> 939 | G9: ='Data Sheet'!F24 -> 899 | H9: ='Data Sheet'!G24 -> 1026 | I9: ='Data Sheet'!H24 -> 1457 | ... L9: ='Data Sheet'!K24 -> 1329 | M9: =Calculation!M14 -> 1972.322 | N9: =Calculation!N14 -> 2170.7799 | O9: =Calculation!O14 -> 2384.9643 | P9: =Calculation!P14 -> 2409.9093 | Q9: =Calculation!Q14 -> 2619.2373
B10: EBITDA | C10: =C5-SUM(C8:C9) -> 18604 | D10: =D5-SUM(D8:D9) -> 18822 | E10: =E5-SUM(E8:E9) -> 20170 | F10: =F5-SUM(F8:F9) -> 22267 | G10: =G5-SUM(G8:G9) -> 27889 | H10: =H5-SUM(H8:H9) -> 31491 | I10: =I5-SUM(I8:I9) -> 35130 | J10: =J5-SUM(J8:J9) -> 36425 | ... Q10: =Q5-SUM(Q8:Q9) -> 71803.795
B11: EBITDA Margin | C11: =C10/C3 -> 0.27165469 | D11: =D10/D3 -> 0.26689544 | E11: =E10/E3 -> 0.24396734 | F11: =F10/F3 -> 0.24525559 | G11: =G10/G3 -> 0.27757982 | H11: =H10/H3 -> 0.25888475 | I11: =I10/I3 -> 0.23935898 | J11: =J10/J3 -> 0.2370339 | ... Q11: =Q10/Q3 -> 0.24884987
B13: ='Data Sheet'!A26 -> Depreciation | C13: ='Data Sheet'!B26 -> 1703 | D13: ='Data Sheet'!C26 -> 1863 | E13: ='Data Sheet'!D26 -> 2011 | F13: ='Data Sheet'!E26 -> 2893 | G13: ='Data Sheet'!F26 -> 3267 | H13: ='Data Sheet'!G26 -> 3476 | I13: ='Data Sheet'!H26 -> 4225 | ... L13: ='Data Sheet'!K26 -> 4902 | M13: =Calculation!M19 -> 4711.642 | N13: =Calculation!N19 -> 4763.7377 | O13: =Calculation!O19 -> 4733.8014 | P13: =Calculation!P19 -> 4813.7466 | Q13: =Calculation!Q19 -> 4946.5198
B14: EBIT | C14: =C10-C13 -> 16901 | D14: =D10-D13 -> 16959 | E14: =E10-E13 -> 18159 | F14: =F10-F13 -> 19374 | G14: =G10-G13 -> 24622 | H14: =H10-H13 -> 28015 | I14: =I10-I13 -> 30905 | J14: =J10-J13 -> 31747 | ... Q14: =Q10-Q13 -> 66857.275
B15: EBIT Margin | C15: =C14/C3 -> 0.24678757 | D15: =D14/D3 -> 0.24047815 | E15: =E14/E3 -> 0.21964318 | F15: =F14/F3 -> 0.2133912 | G15: =G14/G3 -> 0.2450633 | H15: =H14/H3 -> 0.23030886 | I15: =I14/I3 -> 0.21057186 | J15: =J14/J3 -> 0.20659205 | ... Q15: =Q14/Q3 -> 0.23170676
B17: ='Data Sheet'!A27 -> Interest | C17: ='Data Sheet'!B27 -> 0 | D17: ='Data Sheet'!C27 -> 0 | E17: ='Data Sheet'!D27 -> 0 | F17: ='Data Sheet'!E27 -> 170 | G17: ='Data Sheet'!F27 -> 195 | H17: ='Data Sheet'!G27 -> 200 | I17: ='Data Sheet'!H27 -> 284 | ... L17: ='Data Sheet'!K27 -> 416 | M17: =Calculation!M29 -> 271.79132 | N17: =Calculation!N29 -> 298.97046 | O17: =Calculation!O29 -> 328.8675 | P17: =Calculation!P29 -> 361.75425 | Q17: =Calculation!Q29 -> 364.25992
B18: ='Data Sheet'!A25 -> Other Income | C18: ='Data Sheet'!B25 -> 3050 | D18: ='Data Sheet'!C25 -> 3311 | E18: ='Data Sheet'!D25 -> 2882 | F18: ='Data Sheet'!E25 -> 2803 | G18: ='Data Sheet'!F25 -> 2201 | H18: ='Data Sheet'!G25 -> 2295 | I18: ='Data Sheet'!H25 -> 2701 | ... L18: ='Data Sheet'!K25 -> 3033 | M18: =Calculation!M36 -> 5625.8377 | N18: =Calculation!N36 -> 5847.3417 | O18: =Calculation!O36 -> 5961.0275 | P18: =Calculation!P36 -> 6303.0967 | Q18: =Calculation!Q36 -> 6740.2952
B19: EBT | C19: =SUM(C14,C18)-C17 -> 19951 | D19: =SUM(D14,D18)-D17 -> 20270 | E19: =SUM(E14,E18)-E17 -> 21041 | F19: =SUM(F14,F18)-F17 -> 22007 | G19: =SUM(G14,G18)-G17 -> 26628 | H19: =SUM(H14,H18)-H17 -> 30110 | I19: =SUM(I14,I18)-I17 -> 33322 | J19: =SUM(J14,J18)-J17 -> 35988 | ... Q19: =SUM(Q14,Q18)-Q17 -> 73233.31
B20: EBT Margin | C20: =C19/C3 -> 0.29132352 | D20: =D19/D3 -> 0.28742804 | E20: =E19/E3 -> 0.25450257 | F20: =F19/F3 -> 0.24239187 | G20: =G19/G3 -> 0.26502906 | H20: =H19/H3 -> 0.24753167 | I20: =I19/I3 -> 0.22704014 | J20: =J19/J3 -> 0.23419015 | ... Q20: =Q19/Q3 -> 0.25380413
B22: ='Data Sheet'!A29 -> Tax | C22: ='Data Sheet'!B29 -> 5598 | D22: ='Data Sheet'!C29 -> 4241 | E22: ='Data Sheet'!D29 -> 5631 | F22: ='Data Sheet'!E29 -> 5368 | G22: ='Data Sheet'!F29 -> 7205 | H22: ='Data Sheet'!G29 -> 7964 | I22: ='Data Sheet'!H29 -> 9214 | ... L22: ='Data Sheet'!K29 -> 10521 | M22: =Calculation!M41 -> 13217.314 | N22: =Calculation!N41 -> 14361.073 | O22: =Calculation!O41 -> 16024.434 | P22: =Calculation!P41 -> 17699.555 | Q22: =Calculation!Q41 -> 19725.456
B23: Net Profit | C23: =C19-C22 -> 14353 | D23: =D19-D22 -> 16029 | E23: =E19-E22 -> 15410 | F23: =F19-F22 -> 16639 | G23: =G19-G22 -> 19423 | H23: =H19-H22 -> 22146 | I23: =I19-I22 -> 24108 | J23: =J19-J22 -> 26248 | ... Q23: =Q19-Q22 -> 53507.855
B24: Net Profit Margin | C24: =C23/C3 -> 0.2095818 | D24: =D23/D3 -> 0.22729077 | E24: =E23/E3 -> 0.1863925 | F24: =F23/F3 -> 0.18326706 | G24: =G23/G3 -> 0.19331754 | H24: =H23/H3 -> 0.18206033 | I24: =I23/I3 -> 0.16426036 | J24: =J23/J3 -> 0.17080757 | ... Q24: =Q23/Q3 -> 0.18544177
A27: * | B27: ="Balance Sheet For "&'Data Sheet'!B1 -> Balance Sheet For INFOSYS LTD
B28: Shareholders Funds
B29: ='Data Sheet'!A57 -> Equity Share Capital | C29: ='Data Sheet'!B57 -> 1144 | D29: ='Data Sheet'!C57 -> 1088 | E29: ='Data Sheet'!D57 -> 2170 | F29: ='Data Sheet'!E57 -> 2122 | G29: ='Data Sheet'!F57 -> 2124 | H29: ='Data Sheet'!G57 -> 2098 | I29: ='Data Sheet'!H57 -> 2069 | ... L29: ='Data Sheet'!K57 -> 2024 | M29: =L29 -> 2024 | N29: =M29 -> 2024 | O29: =N29 -> 2024 | P29: =O29 -> 2024 | Q29: =P29 -> 2024
B30: ='Data Sheet'!A58 -> Reserves | C30: ='Data Sheet'!B58 -> 67838 | D30: ='Data Sheet'!C58 -> 63835 | E30: ='Data Sheet'!D58 -> 62778 | F30: ='Data Sheet'!E58 -> 63328 | G30: ='Data Sheet'!F58 -> 74227 | H30: ='Data Sheet'!G58 -> 73252 | I30: ='Data Sheet'!H58 -> 73338 | ... L30: ='Data Sheet'!K58 -> 90828 | M30: =Calculation!S14 -> 105689.07 | N30: =Calculation!T14 -> 121516.54 | O30: =Calculation!U14 -> 138075.35 | P30: =Calculation!V14 -> 157662.03 | Q30: =Calculation!W14 -> 179111.99
B31: Total Shareholers Funds | C31: =SUM(C29:C30) -> 68982 | D31: =SUM(D29:D30) -> 64923 | E31: =SUM(E29:E30) -> 64948 | F31: =SUM(F29:F30) -> 65450 | G31: =SUM(G29:G30) -> 76351 | H31: =SUM(H29:H30) -> 75350 | I31: =SUM(I29:I30) -> 75407 | J31: =SUM(J29:J30) -> 88116 | ... Q31: =SUM(Q29:Q30) -> 181135.99
B33: Non-Current Liabilities
B34: ='Data Sheet'!A59 -> Borrowings | C34: ='Data Sheet'!B59 -> 0 | D34: ='Data Sheet'!C59 -> 0 | E34: ='Data Sheet'!D59 -> 0 | F34: ='Data Sheet'!E59 -> 4633 | G34: ='Data Sheet'!F59 -> 5325 | H34: ='Data Sheet'!G59 -> 5474 | I34: ='Data Sheet'!H59 -> 8299 | ... L34: ='Data Sheet'!K59 -> 9176 | M34: =Calculation!S23 -> 9176 | N34: =Calculation!T23 -> 9176 | O34: =Calculation!U23 -> 9176 | P34: =Calculation!V23 -> 9176 | Q34: =Calculation!W23 -> 9176
B35: ='Data Sheet'!A60 -> Other Liabilities | C35: ='Data Sheet'!B60-SUM(C39:C40) -> 13799 | D35: ='Data Sheet'!C60-SUM(D39:D40) -> 13732 | E35: ='Data Sheet'!D60-SUM(E39:E40) -> 17463 | F35: ='Data Sheet'!E60-SUM(F39:F40) -> 18865 | G35: ='Data Sheet'!F60-SUM(G39:G40) -> 23190 | H35: ='Data Sheet'!G60-SUM(H39:H40) -> 31771 | I35: ='Data Sheet'!H60-SUM(I39:I40) -> 37025 | J35: ='Data Sheet'!I60-SUM(J39:J40) -> 35589 | ... L35: ='Data Sheet'!K60-SUM(L39:L40) -> 47516 | M35: =Calculation!M49 -> 45222.947 | N35: =Calculation!N49 -> 50390.531 | O35: =Calculation!O49 -> 56369.409 | P35: =Calculation!P49 -> 62708.562 | Q35: =Calculation!Q49 -> 69925.345
B36: Total Non-Current Liabilities | C36: =SUM(C34:C35) -> 13799 | D36: =SUM(D34:D35) -> 13732 | E36: =SUM(E34:E35) -> 17463 | F36: =SUM(F34:F35) -> 23498 | G36: =SUM(G34:G35) -> 28515 | H36: =SUM(H34:H35) -> 37245 | I36: =SUM(I34:I35) -> 45324 | J36: =SUM(J34:J35) -> 43948 | ... Q36: =SUM(Q34:Q35) -> 79101.345
B38: Current Liabilities
B39: ='Manual Data'!B36 -> Trade Payables | C39: ='Manual Data'!C36 -> 367 | D39: ='Manual Data'!D36 -> 694 | E39: ='Manual Data'!E36 -> 1655 | F39: ='Manual Data'!F36 -> 2852 | G39: ='Manual Data'!G36 -> 2645 | H39: ='Manual Data'!H36 -> 4134 | I39: ='Manual Data'!I36 -> 3865 | ... L39: ='Manual Data'!L36 -> 4744 | M39: =Calculation!M54 -> 4506.0732 | N39: =Calculation!N54 -> 5362.9041 | O39: =Calculation!O54 -> 6278.4267 | P39: =Calculation!P54 -> 7082.7691 | Q39: =Calculation!Q54 -> 7664.9531
B40: ='Manual Data'!B37 -> Advance from Customers | C40: ='Manual Data'!C37 -> 0 | D40: ='Manual Data'!D37 -> 0 | E40: ='Manual Data'!E37 -> 0 | F40: ='Manual Data'!F37 -> 0 | G40: ='Manual Data'!G37 -> 0 | H40: ='Manual Data'!H37 -> 0 | I40: ='Manual Data'!I37 -> 0 | ... L40: ='Manual Data'!L37 -> 0 | M40: =L40 -> 0 | N40: =M40 -> 0 | O40: =N40 -> 0 | P40: =O40 -> 0 | Q40: =P40 -> 0
B41: Total Current Liabilities | C41: =SUM(C39:C40) -> 367 | D41: =SUM(D39:D40) -> 694 | E41: =SUM(E39:E40) -> 1655 | F41: =SUM(F39:F40) -> 2852 | G41: =SUM(G39:G40) -> 2645 | H41: =SUM(H39:H40) -> 4134 | I41: =SUM(I39:I40) -> 3865 | J41: =SUM(J39:J40) -> 3956 | ... Q41: =SUM(Q39:Q40) -> 7664.9531
B43: Total Liabilities | C43: =SUM(C41,C36) -> 14166 | D43: =SUM(D41,D36) -> 14426 | E43: =SUM(E41,E36) -> 19118 | F43: =SUM(F41,F36) -> 26350 | G43: =SUM(G41,G36) -> 31160 | H43: =SUM(H41,H36) -> 41379 | I43: =SUM(I41,I36) -> 49189 | J43: =SUM(J41,J36) -> 47904 | ... Q43: =SUM(Q41,Q36) -> 86766.298
B45: Total Liabilities & Shareholer's Funds | C45: =SUM(C41,C36,C31) -> 83148 | D45: =SUM(D41,D36,D31) -> 79349 | E45: =SUM(E41,E36,E31) -> 84066 | F45: =SUM(F41,F36,F31) -> 91800 | G45: =SUM(G41,G36,G31) -> 107511 | H45: =SUM(H41,H36,H31) -> 116729 | I45: =SUM(I41,I36,I31) -> 124596 | J45: =SUM(J41,J36,J31) -> 136020 | ... Q45: =SUM(Q41,Q36,Q31) -> 267902.29
B47: Non-Current Assets
B48: ='Data Sheet'!A62 -> Net Block | C48: ='Data Sheet'!B62 -> 14179 | D48: ='Data Sheet'!C62 -> 12574 | E48: ='Data Sheet'!D62 -> 15710 | F48: ='Data Sheet'!E62 -> 23789 | G48: ='Data Sheet'!F62 -> 25505 | H48: ='Data Sheet'!G62 -> 25800 | I48: ='Data Sheet'!H62 -> 29225 | ... L48: ='Data Sheet'!K62 -> 33770 | M48: =Calculation!S7 -> 33664.389 | N48: =Calculation!T7 -> 33604.963 | O48: =Calculation!U7 -> 33891.802 | P48: =Calculation!V7 -> 34381.206 | Q48: =Calculation!W7 -> 34804.176
B49: ='Data Sheet'!A63 -> Capital Work in Progress | C49: ='Data Sheet'!B63 -> 1365 | D49: ='Data Sheet'!C63 -> 1606 | E49: ='Data Sheet'!D63 -> 1388 | F49: ='Data Sheet'!E63 -> 954 | G49: ='Data Sheet'!F63 -> 922 | H49: ='Data Sheet'!G63 -> 416 | I49: ='Data Sheet'!H63 -> 288 | ... L49: ='Data Sheet'!K63 -> 526 | M49: =Calculation!M66 -> 1572.295 | N49: =Calculation!N66 -> 1402.9594 | O49: =Calculation!O66 -> 1123.5487 | P49: =Calculation!P66 -> 949.9876 | Q49: =Calculation!Q66 -> 918.26848
B50: ='Data Sheet'!A64 -> Investments | C50: ='Data Sheet'!B64 -> 16423 | D50: ='Data Sheet'!C64 -> 12163 | E50: ='Data Sheet'!D64 -> 11261 | F50: ='Data Sheet'!E64 -> 8792 | G50: ='Data Sheet'!F64 -> 14205 | H50: ='Data Sheet'!G64 -> 20324 | I50: ='Data Sheet'!H64 -> 19478 | ... L50: ='Data Sheet'!K64 -> 21880 | M50: =Calculation!M62 -> 29762.378 | N50: =Calculation!N62 -> 30843.324 | O50: =Calculation!O62 -> 33233.679 | P50: =Calculation!P62 -> 36664.939 | Q50: =Calculation!Q62 -> 41595.806
B51: ='Data Sheet'!A65 -> Other Assets | C51: ='Data Sheet'!B65-SUM(C55:C57) -> 16234 | D51: ='Data Sheet'!C65-SUM(D55:D57) -> 20046 | E51: ='Data Sheet'!D65-SUM(E55:E57) -> 21312 | F51: ='Data Sheet'!E65-SUM(F55:F57) -> 21129 | G51: ='Data Sheet'!F65-SUM(G55:G57) -> 22871 | H51: ='Data Sheet'!G65-SUM(H55:H57) -> 30019 | I51: ='Data Sheet'!H65-SUM(I55:I57) -> 38008 | J51: ='Data Sheet'!I65-SUM(J55:J57) -> 38503 | ... L51: ='Data Sheet'!K65-SUM(L55:L57) -> 40677 | M51: =Calculation!M70 -> 48166.323 | N51: =Calculation!N70 -> 53184.578 | O51: =Calculation!O70 -> 57619.554 | P51: =Calculation!P70 -> 63001.592 | Q51: =Calculation!Q70 -> 69560.593
...

Sheet Ratios Analysis
B1: ="Ratios Analysis for "&'Data Sheet'!B1 -> Ratios Analysis for INFOSYS LTD
B2: ='Data Sheet'!A16 -> Report Date | C2: ='Data Sheet'!B16 -> 42825 | D2: ='Data Sheet'!C16 -> 43190 | E2: ='Data Sheet'!D16 -> 43555 | F2: ='Data Sheet'!E16 -> 43921 | G2: ='Data Sheet'!F16 -> 44286 | H2: ='Data Sheet'!G16 -> 44651 | I2: ='Data Sheet'!H16 -> 45016 | ... L2: ='Data Sheet'!K16 -> 46112 | M2: =L2+365 -> 46477 | N2: =M2+365 -> 46842 | O2: =N2+365 -> 47207 | P2: =O2+365 -> 47572 | Q2: =P2+365 -> 47937
A3: * | B3: Profitability Ratios
B4: Gross Profit Margin | C4: ='Historical Financial Statement'!C6 -> 0.34862158 | D4: ='Historical Financial Statement'!D6 -> 0.34212019 | E4: ='Historical Financial Statement'!E6 -> 0.32934986 | F4: ='Historical Financial Statement'!F6 -> 0.31479993 | G4: ='Historical Financial Statement'!G6 -> 0.31831754 | H4: ='Historical Financial Statement'!H6 -> 0.30271043 | I4: ='Historical Financial Statement'!I6 -> 0.28539794 | J4: ='Historical Financial Statement'!J6 -> 0.28398516 | ... Q4: ='Historical Financial Statement'!Q6 -> 0.29720635
B5: EBITDA Margin | C5: ='Historical Financial Statement'!C11 -> 0.27165469 | D5: ='Historical Financial Statement'!D11 -> 0.26689544 | E5: ='Historical Financial Statement'!E11 -> 0.24396734 | F5: ='Historical Financial Statement'!F11 -> 0.24525559 | G5: ='Historical Financial Statement'!G11 -> 0.27757982 | H5: ='Historical Financial Statement'!H11 -> 0.25888475 | I5: ='Historical Financial Statement'!I11 -> 0.23935898 | J5: ='Historical Financial Statement'!J11 -> 0.2370339 | ... Q5: ='Historical Financial Statement'!Q11 -> 0.24884987
B6: EBIT Margin | C6: ='Historical Financial Statement'!C15 -> 0.24678757 | D6: ='Historical Financial Statement'!D15 -> 0.24047815 | E6: ='Historical Financial Statement'!E15 -> 0.21964318 | F6: ='Historical Financial Statement'!F15 -> 0.2133912 | G6: ='Historical Financial Statement'!G15 -> 0.2450633 | H6: ='Historical Financial Statement'!H15 -> 0.23030886 | I6: ='Historical Financial Statement'!I15 -> 0.21057186 | J6: ='Historical Financial Statement'!J15 -> 0.20659205 | ... Q6: ='Historical Financial Statement'!Q15 -> 0.23170676
B7: Net Profit Margin | C7: ='Historical Financial Statement'!C24 -> 0.2095818 | D7: ='Historical Financial Statement'!D24 -> 0.22729077 | E7: ='Historical Financial Statement'!E24 -> 0.1863925 | F7: ='Historical Financial Statement'!F24 -> 0.18326706 | G7: ='Historical Financial Statement'!G24 -> 0.19331754 | H7: ='Historical Financial Statement'!H24 -> 0.18206033 | I7: ='Historical Financial Statement'!I24 -> 0.16426036 | J7: ='Historical Financial Statement'!J24 -> 0.17080757 | ... Q7: ='Historical Financial Statement'!Q24 -> 0.18544177
B8: Return on Equity | C8: ='Historical Financial Statement'!C23/SUM('Historical Financial Statement'!C29:C30) -> 0.20806877 | D8: ='Historical Financial Statement'!D23/SUM('Historical Financial Statement'!D29:D30) -> 0.24689247 | E8: ='Historical Financial Statement'!E23/SUM('Historical Financial Statement'!E29:E30) -> 0.23726674 | F8: ='Historical Financial Statement'!F23/SUM('Historical Financial Statement'!F29:F30) -> 0.2542246 | G8: ='Historical Financial Statement'!G23/SUM('Historical Financial Statement'!G29:G30) -> 0.25439091 | H8: ='Historical Financial Statement'!H23/SUM('Historical Financial Statement'!H29:H30) -> 0.29390843 | I8: ='Historical Financial Statement'!I23/SUM('Historical Financial Statement'!I29:I30) -> 0.31970507 | J8: ='Historical Financial Statement'!J23/SUM('Historical Financial Statement'!J29:J30) -> 0.29788007 | ... Q8: ='Historical Financial Statement'!Q23/SUM('Historical Financial Statement'!Q29:Q30) -> 0.29540156
B9: Return on Assets | C9: ='Historical Financial Statement'!C23/'Historical Financial Statement'!C60 -> 0.17261991 | D9: ='Historical Financial Statement'!D23/'Historical Financial Statement'!D60 -> 0.20200633 | E9: ='Historical Financial Statement'!E23/'Historical Financial Statement'!E60 -> 0.18330835 | F9: ='Historical Financial Statement'!F23/'Historical Financial Statement'!F60 -> 0.18125272 | G9: ='Historical Financial Statement'!G23/'Historical Financial Statement'!G60 -> 0.18066058 | H9: ='Historical Financial Statement'!H23/'Historical Financial Statement'!H60 -> 0.18972149 | I9: ='Historical Financial Statement'!I23/'Historical Financial Statement'!I60 -> 0.19348936 | J9: ='Historical Financial Statement'!J23/'Historical Financial Statement'!J60 -> 0.19297162 | ... Q9: ='Historical Financial Statement'!Q23/'Historical Financial Statement'!Q60 -> 0.19972899
B10: Return on Capital Employed | C10: ='Historical Financial Statement'!C14/SUM('Historical Financial Statement'!C29:C30,'Historical Financial Statement'!C34) -> 0.24500594 | D10: ='Historical Financial Statement'!D14/SUM('Historical Financial Statement'!D29:D30,'Historical Financial Statement'!D34) -> 0.26121713 | E10: ='Historical Financial Statement'!E14/SUM('Historical Financial Statement'!E29:E30,'Historical Financial Statement'!E34) -> 0.27959291 | F10: ='Historical Financial Statement'!F14/SUM('Historical Financial Statement'!F29:F30,'Historical Financial Statement'!F34) -> 0.27644365 | G10: ='Historical Financial Statement'!G14/SUM('Historical Financial Statement'!G29:G30,'Historical Financial Statement'!G34) -> 0.30145943 | H10: ='Historical Financial Statement'!H14/SUM('Historical Financial Statement'!H29:H30,'Historical Financial Statement'!H34) -> 0.34661734 | I10: ='Historical Financial Statement'!I14/SUM('Historical Financial Statement'!I29:I30,'Historical Financial Statement'!I34) -> 0.3692089 | J10: ='Historical Financial Statement'!J14/SUM('Historical Financial Statement'!J29:J30,'Historical Financial Statement'!J34) -> 0.32906971 | ... Q10: ='Historical Financial Statement'!Q14/SUM('Historical Financial Statement'!Q29:Q30,'Historical Financial Statement'!Q34) -> 0.35130353
B11: Reuturn on Invested Capital Employed | C11: ='Historical Financial Statement'!C23/SUM('Historical Financial Statement'!C31,'Historical Financial Statement'!C34) -> 0.20806877 | D11: ='Historical Financial Statement'!D23/SUM('Historical Financial Statement'!D31,'Historical Financial Statement'!D34) -> 0.24689247 | E11: ='Historical Financial Statement'!E23/SUM('Historical Financial Statement'!E31,'Historical Financial Statement'!E34) -> 0.23726674 | F11: ='Historical Financial Statement'!F23/SUM('Historical Financial Statement'!F31,'Historical Financial Statement'!F34) -> 0.23741849 | G11: ='Historical Financial Statement'!G23/SUM('Historical Financial Statement'!G31,'Historical Financial Statement'!G34) -> 0.23780548 | H11: ='Historical Financial Statement'!H23/SUM('Historical Financial Statement'!H31,'Historical Financial Statement'!H34) -> 0.27400277 | I11: ='Historical Financial Statement'!I23/SUM('Historical Financial Statement'!I31,'Historical Financial Statement'!I34) -> 0.28800803 | J11: ='Historical Financial Statement'!J23/SUM('Historical Financial Statement'!J31,'Historical Financial Statement'!J34) -> 0.27207048 | ... Q11: ='Historical Financial Statement'!Q23/SUM('Historical Financial Statement'!Q31,'Historical Financial Statement'!Q34) -> 0.2811586
A13: * | B13: Solvency Ratios
B14: D/E Ratio | C14: ='Historical Financial Statement'!C34/SUM('Historical Financial Statement'!C29:C30) -> 0 | D14: ='Historical Financial Statement'!D34/SUM('Historical Financial Statement'!D29:D30) -> 0 | E14: ='Historical Financial Statement'!E34/SUM('Historical Financial Statement'!E29:E30) -> 0 | F14: ='Historical Financial Statement'!F34/SUM('Historical Financial Statement'!F29:F30) -> 0.07078686 | G14: ='Historical Financial Statement'!G34/SUM('Historical Financial Statement'!G29:G30) -> 0.069743684 | H14: ='Historical Financial Statement'!H34/SUM('Historical Financial Statement'!H29:H30) -> 0.072647644 | I14: ='Historical Financial Statement'!I34/SUM('Historical Financial Statement'!I29:I30) -> 0.1100561 | J14: ='Historical Financial Statement'!J34/SUM('Historical Financial Statement'!J29:J30) -> 0.094863589 | ... Q14: ='Historical Financial Statement'!Q34/SUM('Historical Financial Statement'!Q29:Q30) -> 0.050658071
B15: Debt Ratio | C15: ='Historical Financial Statement'!C34/'Historical Financial Statement'!C60 -> 0 | D15: ='Historical Financial Statement'!D34/'Historical Financial Statement'!D60 -> 0 | E15: ='Historical Financial Statement'!E34/'Historical Financial Statement'!E60 -> 0 | F15: ='Historical Financial Statement'!F34/'Historical Financial Statement'!F60 -> 0.05046841 | G15: ='Historical Financial Statement'!G34/'Historical Financial Statement'!G60 -> 0.049529816 | H15: ='Historical Financial Statement'!H34/'Historical Financial Statement'!H60 -> 0.046894945 | I15: ='Historical Financial Statement'!I34/'Historical Financial Statement'!I60 -> 0.066607275 | J15: ='Historical Financial Statement'!J34/'Historical Financial Statement'!J60 -> 0.061454198 | ... Q15: ='Historical Financial Statement'!Q34/'Historical Financial Statement'!Q60 -> 0.034251293
B16: Interest Coverage Ratio | C16: =IFERROR('Historical Financial Statement'!C19/'Historical Financial Statement'!C17,0) -> 0 | D16: =IFERROR('Historical Financial Statement'!D19/'Historical Financial Statement'!D17,0) -> 0 | E16: =IFERROR('Historical Financial Statement'!E19/'Historical Financial Statement'!E17,0) -> 0 | F16: =IFERROR('Historical Financial Statement'!F19/'Historical Financial Statement'!F17,0) -> 129.45294 | G16: =IFERROR('Historical Financial Statement'!G19/'Historical Financial Statement'!G17,0) -> 136.55385 | H16: =IFERROR('Historical Financial Statement'!H19/'Historical Financial Statement'!H17,0) -> 150.55 | I16: =IFERROR('Historical Financial Statement'!I19/'Historical Financial Statement'!I17,0) -> 117.33099 | J16: =IFERROR('Historical Financial Statement'!J19/'Historical Financial Statement'!J17,0) -> 76.570213 | ... Q16: =IFERROR('Historical Financial Statement'!Q19/'Historical Financial Statement'!Q17,0) -> 201.04685
A18: * | B18: Efficency Ratios
B19: Assets Turnover Ratio | C19: ='Historical Financial Statement'!C3/'Historical Financial Statement'!C60 -> 0.82363977 | D19: ='Historical Financial Statement'!D3/'Historical Financial Statement'!D60 -> 0.88875726 | E19: ='Historical Financial Statement'!E3/'Historical Financial Statement'!E60 -> 0.98345348 | F19: ='Historical Financial Statement'!F3/'Historical Financial Statement'!F60 -> 0.98900871 | G19: ='Historical Financial Statement'!G3/'Historical Financial Statement'!G60 -> 0.93452763 | H19: ='Historical Financial Statement'!H3/'Historical Financial Statement'!H60 -> 1.0420804 | I19: ='Historical Financial Statement'!I3/'Historical Financial Statement'!I60 -> 1.1779431 | J19: ='Historical Financial Statement'!J3/'Historical Financial Statement'!J60 -> 1.1297603 | ... Q19: ='Historical Financial Statement'!Q3/'Historical Financial Statement'!Q60 -> 1.0770442
B20: Fixed Assets Turnover Ratio | C20: ='Historical Financial Statement'!C3/'Historical Financial Statement'!C48 -> 4.8299598 | D20: ='Historical Financial Statement'!D3/'Historical Financial Statement'!D48 -> 5.6085573 | E20: ='Historical Financial Statement'!E3/'Historical Financial Statement'!E48 -> 5.2625716 | F20: ='Historical Financial Statement'!F3/'Historical Financial Statement'!F48 -> 3.8165118 | G20: ='Historical Financial Statement'!G3/'Historical Financial Statement'!G48 -> 3.939306 | H20: ='Historical Financial Statement'!H3/'Historical Financial Statement'!H48 -> 4.7147674 | I20: ='Historical Financial Statement'!I3/'Historical Financial Statement'!I48 -> 5.0219675 | J20: ='Historical Financial Statement'!J3/'Historical Financial Statement'!J48 -> 5.5633191 | ... Q20: ='Historical Financial Statement'!Q3/'Historical Financial Statement'!Q48 -> 8.2904598
B21: Inventory Turnover Ratio | C21: =IFERROR('Historical Financial Statement'!C4/'Historical Financial Statement'!C56,0) -> 0 | D21: =IFERROR('Historical Financial Statement'!D4/'Historical Financial Statement'!D56,0) -> 0 | E21: =IFERROR('Historical Financial Statement'!E4/'Historical Financial Statement'!E56,0) -> 0 | F21: =IFERROR('Historical Financial Statement'!F4/'Historical Financial Statement'!F56,0) -> 0 | G21: =IFERROR('Historical Financial Statement'!G4/'Historical Financial Statement'!G56,0) -> 0 | H21: =IFERROR('Historical Financial Statement'!H4/'Historical Financial Statement'!H56,0) -> 0 | I21: =IFERROR('Historical Financial Statement'!I4/'Historical Financial Statement'!I56,0) -> 0 | J21: =IFERROR('Historical Financial Statement'!J4/'Historical Financial Statement'!J56,0) -> 0 | ... Q21: =IFERROR('Historical Financial Statement'!Q4/'Historical Financial Statement'!Q56,0) -> 0
B22: Trade Payable Turnover Ratio | C22: ='Historical Financial Statement'!C4/'Historical Financial Statement'!C39 -> 121.55041 | D22: ='Historical Financial Statement'!D4/'Historical Financial Statement'!D39 -> 66.851585 | E22: ='Historical Financial Statement'!E4/'Historical Financial Statement'!E39 -> 33.502115 | F22: ='Historical Financial Statement'!F4/'Historical Financial Statement'!F39 -> 21.812763 | G22: ='Historical Financial Statement'!G4/'Historical Financial Statement'!G39 -> 25.89414 | H22: ='Historical Financial Statement'!H4/'Historical Financial Statement'!H39 -> 20.517417 | I22: ='Historical Financial Statement'!I4/'Historical Financial Statement'!I39 -> 27.135834 | J22: ='Historical Financial Statement'!J4/'Historical Financial Statement'!J39 -> 27.813448 | ... Q22: ='Historical Financial Statement'!Q4/'Historical Financial Statement'!Q39 -> 26.456251
B23: Trade Receivable Turnover Ratio | C23: ='Historical Financial Statement'!C3/'Historical Financial Statement'!C55 -> 5.557864 | D23: ='Historical Financial Statement'!D3/'Historical Financial Statement'!D55 -> 5.3661543 | E23: ='Historical Financial Statement'!E3/'Historical Financial Statement'!E55 -> 5.5759763 | F23: ='Historical Financial Statement'!F3/'Historical Financial Statement'!F55 -> 4.9110726 | G23: ='Historical Financial Statement'!G3/'Historical Financial Statement'!G55 -> 5.207422 | H23: ='Historical Financial Statement'!H3/'Historical Financial Statement'!H55 -> 5.3591065 | I23: ='Historical Financial Statement'!I3/'Historical Financial Statement'!I55 -> 5.7727738 | J23: ='Historical Financial Statement'!J3/'Historical Financial Statement'!J55 -> 5.0895903 | ... Q23: ='Historical Financial Statement'!Q3/'Historical Financial Statement'!Q55 -> 5.2759837
A25: * | B25: Liquidity Ratios
B26: Current Ratio | C26: ='Historical Financial Statement'!C58/'Historical Financial Statement'!C41 -> 95.223433 | D26: ='Historical Financial Statement'!D58/'Historical Financial Statement'!D41 -> 47.492795 | E26: ='Historical Financial Statement'!E58/'Historical Financial Statement'!E41 -> 20.782477 | F26: ='Historical Financial Statement'!F58/'Historical Financial Statement'!F41 -> 13.021038 | G26: ='Historical Financial Statement'!G58/'Historical Financial Statement'!G41 -> 16.638185 | H26: ='Historical Financial Statement'!H58/'Historical Financial Statement'!H41 -> 9.7169811 | I26: ='Historical Financial Statement'!I58/'Historical Financial Statement'!I41 -> 9.727555 | J26: ='Historical Financial Statement'!J58/'Historical Financial Statement'!J41 -> 11.369818 | ... Q26: ='Historical Financial Statement'!Q58/'Historical Financial Statement'!Q41 -> 15.789196
B27: Quick Ratio | C27: =(SUM('Historical Financial Statement'!C55,'Historical Financial Statement'!C57)-'Historical Financial Statement'!C56)/'Historical Financial Statement'!C41 -> 95.223433 | D27: =(SUM('Historical Financial Statement'!D55,'Historical Financial Statement'!D57)-'Historical Financial Statement'!D56)/'Historical Financial Statement'!D41 -> 47.492795 | E27: =(SUM('Historical Financial Statement'!E55,'Historical Financial Statement'!E57)-'Historical Financial Statement'!E56)/'Historical Financial Statement'!E41 -> 20.782477 | F27: =(SUM('Historical Financial Statement'!F55,'Historical Financial Statement'!F57)-'Historical Financial Statement'!F56)/'Historical Financial Statement'!F41 -> 13.021038 | G27: =(SUM('Historical Financial Statement'!G55,'Historical Financial Statement'!G57)-'Historical Financial Statement'!G56)/'Historical Financial Statement'!G41 -> 16.638185 | H27: =(SUM('Historical Financial Statement'!H55,'Historical Financial Statement'!H57)-'Historical Financial Statement'!H56)/'Historical Financial Statement'!H41 -> 9.7169811 | I27: =(SUM('Historical Financial Statement'!I55,'Historical Financial Statement'!I57)-'Historical Financial Statement'!I56)/'Historical Financial Statement'!I41 -> 9.727555 | J27: =(SUM('Historical Financial Statement'!J55,'Historical Financial Statement'!J57)-'Historical Financial Statement'!J56)/'Historical Financial Statement'!J41 -> 11.369818 | ... Q27: =(SUM('Historical Financial Statement'!Q55,'Historical Financial Statement'!Q57)-'Historical Financial Statement'!Q56)/'Historical Financial Statement'!Q41 -> 15.789196
B28: Cash Ratio | C28: ='Historical Financial Statement'!C57/'Historical Financial Statement'!C41 -> 61.648501 | D28: ='Historical Financial Statement'!D57/'Historical Financial Statement'!D41 -> 28.556196 | E28: ='Historical Financial Statement'!E57/'Historical Financial Statement'!E41 -> 11.823565 | F28: ='Historical Financial Statement'!F57/'Historical Financial Statement'!F41 -> 6.5389201 | G28: ='Historical Financial Statement'!G57/'Historical Financial Statement'!G41 -> 9.3436673 | H28: ='Historical Financial Statement'!H57/'Historical Financial Statement'!H41 -> 4.2264151 | I28: ='Historical Financial Statement'!I57/'Historical Financial Statement'!I41 -> 3.1495472 | J28: ='Historical Financial Statement'!J57/'Historical Financial Statement'!J41 -> 3.7376138 | ... Q28: ='Historical Financial Statement'!Q57/'Historical Financial Statement'!Q41 -> 8.6541462
A30: * | B30: Market Ratios
B31: Eairning Per Share | C31: ='Historical Financial Statement'!C23/'Data Sheet'!B93 -> 31.243606 | D31: ='Historical Financial Statement'!D23/'Data Sheet'!C93 -> 36.694748 | E31: ='Historical Financial Statement'!E23/'Data Sheet'!D93 -> 35.272036 | F31: ='Historical Financial Statement'!F23/'Data Sheet'!E93 -> 39.067856 | G31: ='Historical Financial Statement'!G23/'Data Sheet'!F93 -> 45.586406 | H31: ='Historical Financial Statement'!H23/'Data Sheet'!G93 -> 52.644591 | I31: ='Historical Financial Statement'!I23/'Data Sheet'!H93 -> 58.11117 | J31: ='Historical Financial Statement'!J23/'Data Sheet'!I93 -> 63.234479 | ... L31: ='Historical Financial Statement'!L23/'Data Sheet'!K93 -> 72.67482 | M31: =_xlfn.FORECAST.ETS(M$2,$C31:$L31,$C$2:$L$2) -> 76.650634 | N31: =_xlfn.FORECAST.ETS(N$2,$C31:$L31,$C$2:$L$2) -> 81.30807 | O31: =_xlfn.FORECAST.ETS(O$2,$C31:$L31,$C$2:$L$2) -> 85.978232 | P31: =_xlfn.FORECAST.ETS(P$2,$C31:$L31,$C$2:$L$2) -> 90.648429 | Q31: =_xlfn.FORECAST.ETS(Q$2,$C31:$L31,$C$2:$L$2) -> 95.318626
B32: P/E Ratio | C32: ='Data Sheet'!B90/'Ratios Analysis'!C31 -> 16.359507 | D32: ='Data Sheet'!C90/'Ratios Analysis'!D31 -> 15.421825 | E32: ='Data Sheet'!D90/'Ratios Analysis'!E31 -> 21.088944 | F32: ='Data Sheet'!E90/'Ratios Analysis'!F31 -> 16.420148 | G32: ='Data Sheet'!F90/'Ratios Analysis'!G31 -> 30.010043 | H32: ='Data Sheet'!G90/'Ratios Analysis'!H31 -> 36.221195 | I32: ='Data Sheet'!H90/'Ratios Analysis'!I31 -> 24.572728 | J32: ='Data Sheet'!I90/'Ratios Analysis'!J31 -> 23.690398 | ... L32: ='Data Sheet'!K90/'Ratios Analysis'!L31 -> 17.208161 | M32: =_xlfn.FORECAST.ETS(M$2,$C32:$L32,$C$2:$L$2) -> 22.460569 | N32: =_xlfn.FORECAST.ETS(N$2,$C32:$L32,$C$2:$L$2) -> 23.148248 | O32: =_xlfn.FORECAST.ETS(O$2,$C32:$L32,$C$2:$L$2) -> 23.837806 | P32: =_xlfn.FORECAST.ETS(P$2,$C32:$L32,$C$2:$L$2) -> 24.527369 | Q32: =_xlfn.FORECAST.ETS(Q$2,$C32:$L32,$C$2:$L$2) -> 25.216932
B33: Book Value Per Share | C33: =SUM('Historical Financial Statement'!C29:C30)/'Data Sheet'!B93 -> 150.15999 | D33: =SUM('Historical Financial Statement'!D29:D30)/'Data Sheet'!C93 -> 148.62644 | E33: =SUM('Historical Financial Statement'!E29:E30)/'Data Sheet'!D93 -> 148.65985 | F33: =SUM('Historical Financial Statement'!F29:F30)/'Data Sheet'!E93 -> 153.67457 | G33: =SUM('Historical Financial Statement'!G29:G30)/'Data Sheet'!F93 -> 179.19825 | H33: =SUM('Historical Financial Statement'!H29:H30)/'Data Sheet'!G93 -> 179.11902 | I33: =SUM('Historical Financial Statement'!I29:I30)/'Data Sheet'!H93 -> 181.76493 | J33: =SUM('Historical Financial Statement'!J29:J30)/'Data Sheet'!I93 -> 212.28167 | ... L33: =SUM('Historical Financial Statement'!L29:L30)/'Data Sheet'!K93 -> 228.94763 | M33: =_xlfn.FORECAST.ETS(M$2,$C33:$L33,$C$2:$L$2) -> 241.34758 | N33: =_xlfn.FORECAST.ETS(N$2,$C33:$L33,$C$2:$L$2) -> 251.52304 | O33: =_xlfn.FORECAST.ETS(O$2,$C33:$L33,$C$2:$L$2) -> 261.72631 | P33: =_xlfn.FORECAST.ETS(P$2,$C33:$L33,$C$2:$L$2) -> 271.92966 | Q33: =_xlfn.FORECAST.ETS(Q$2,$C33:$L33,$C$2:$L$2) -> 282.13301
A35: * | B35: Operating Cycle Ratios
B36: Inventory Days | C36: =IFERROR(365/C21,0) -> 0 | D36: =IFERROR(365/D21,0) -> 0 | E36: =IFERROR(365/E21,0) -> 0 | F36: =IFERROR(365/F21,0) -> 0 | G36: =IFERROR(365/G21,0) -> 0 | H36: =IFERROR(365/H21,0) -> 0 | I36: =IFERROR(365/I21,0) -> 0 | J36: =IFERROR(365/J21,0) -> 0 | ... Q36: =IFERROR(365/Q21,0) -> 0
B37: Trade Payable Days | C37: =365/C22 -> 3.0028694 | D37: =365/D22 -> 5.4598556 | E37: =365/E22 -> 10.894835 | F37: =365/F22 -> 16.733323 | G37: =365/G22 -> 14.095853 | H37: =365/H22 -> 17.789764 | I37: =365/I22 -> 13.450849 | J37: =365/J22 -> 13.123148 | ... Q37: =365/Q22 -> 13.796362
B38: Trade Receivable Days | C38: =365/C23 -> 65.672712 | D38: =365/D23 -> 68.018916 | E38: =365/E23 -> 65.459389 | F38: =365/F23 -> 74.321849 | G38: =365/G23 -> 70.092265 | H38: =365/H23 -> 68.108368 | I38: =365/I23 -> 63.227837 | J38: =365/J23 -> 71.715006 | ... Q38: =365/Q23 -> 69.181412
B39: Cash Conversion Cycle | C39: =SUM(C36,C38)-C37 -> 62.669842 | D39: =SUM(D36,D38)-D37 -> 62.55906 | E39: =SUM(E36,E38)-E37 -> 54.564555 | F39: =SUM(F36,F38)-F37 -> 57.588526 | G39: =SUM(G36,G38)-G37 -> 55.996411 | H39: =SUM(H36,H38)-H37 -> 50.318604 | I39: =SUM(I36,I38)-I37 -> 49.776989 | J39: =SUM(J36,J38)-J37 -> 58.591858 | ... Q39: =SUM(Q36,Q38)-Q37 -> 55.38505
A41: * | B41: Market Prospect Ratios
B42: Dividend Payout Ratio | C42: ='Data Sheet'!B31/'Historical Financial Statement'!C23 -> 0.41047865 | D42: ='Data Sheet'!C31/'Historical Financial Statement'!D23 -> 0.59052966 | E42: ='Data Sheet'!D31/'Historical Financial Statement'!E23 -> 0.59847502 | F42: ='Data Sheet'!E31/'Historical Financial Statement'!F23 -> 0.44636096 | G42: ='Data Sheet'!F31/'Historical Financial Statement'!G23 -> 0.5905164 | H42: ='Data Sheet'!G31/'Historical Financial Statement'!H23 -> 0.58735663 | I42: ='Data Sheet'!H31/'Historical Financial Statement'!I23 -> 0.58359051 | J42: ='Data Sheet'!I31/'Historical Financial Statement'!J23 -> 0.7258915 | ... L42: ='Data Sheet'!K31/'Historical Financial Statement'!L23 -> 0.65923865 | M42: =_xlfn.FORECAST.ETS(M$2,$C42:$L42,$C$2:$L$2) -> 0.70855164 | N42: =_xlfn.FORECAST.ETS(N$2,$C42:$L42,$C$2:$L$2) -> 0.73187381 | O42: =_xlfn.FORECAST.ETS(O$2,$C42:$L42,$C$2:$L$2) -> 0.7552597 | P42: =_xlfn.FORECAST.ETS(P$2,$C42:$L42,$C$2:$L$2) -> 0.77864577 | Q42: =_xlfn.FORECAST.ETS(Q$2,$C42:$L42,$C$2:$L$2) -> 0.80203183
B43: Retention Ratio | C43: =1-C42 -> 0.58952135 | D43: =1-D42 -> 0.40947034 | E43: =1-E42 -> 0.40152498 | F43: =1-F42 -> 0.55363904 | G43: =1-G42 -> 0.4094836 | H43: =1-H42 -> 0.41264337 | I43: =1-I42 -> 0.41640949 | J43: =1-J42 -> 0.2741085 | ... Q43: =1-Q42 -> 0.19796817
B44: Sustainability Ratio | C44: =C43*C8 -> 0.12266098 | D44: =D43*D8 -> 0.10109514 | E44: =E43*E8 -> 0.095268523 | F44: =F43*F8 -> 0.14074866 | G44: =G43*G8 -> 0.1041689 | H44: =H43*H8 -> 0.12127936 | I44: =I43*I8 -> 0.13312822 | J44: =J43*J8 -> 0.081651459 | ... Q44: =Q43*Q8 -> 0.058480104

Sheet DuPont Model
B1: ="DuPont Models for "&'Data Sheet'!B1 -> DuPont Models for INFOSYS LTD
B2: ='Data Sheet'!A16 -> Report Date | C2: ='Data Sheet'!B16 -> 42825 | D2: ='Data Sheet'!C16 -> 43190 | E2: ='Data Sheet'!D16 -> 43555 | F2: ='Data Sheet'!E16 -> 43921 | G2: ='Data Sheet'!F16 -> 44286 | H2: ='Data Sheet'!G16 -> 44651 | I2: ='Data Sheet'!H16 -> 45016 | ... L2: ='Data Sheet'!K16 -> 46112 | M2: =L2+365 -> 46477 | N2: =M2+365 -> 46842 | O2: =N2+365 -> 47207 | P2: =O2+365 -> 47572 | Q2: =P2+365 -> 47937
B3: Net Profit Margin | C3: ='Ratios Analysis'!C7 -> 0.2095818 | D3: ='Ratios Analysis'!D7 -> 0.22729077 | E3: ='Ratios Analysis'!E7 -> 0.1863925 | F3: ='Ratios Analysis'!F7 -> 0.18326706 | G3: ='Ratios Analysis'!G7 -> 0.19331754 | H3: ='Ratios Analysis'!H7 -> 0.18206033 | I3: ='Ratios Analysis'!I7 -> 0.16426036 | J3: ='Ratios Analysis'!J7 -> 0.17080757 | ... Q3: ='Ratios Analysis'!Q7 -> 0.18544177
B4: Tax Burden | C4: ='Historical Financial Statement'!C23/'Historical Financial Statement'!C19 -> 0.71941256 | D4: ='Historical Financial Statement'!D23/'Historical Financial Statement'!D19 -> 0.79077454 | E4: ='Historical Financial Statement'!E23/'Historical Financial Statement'!E19 -> 0.73237964 | F4: ='Historical Financial Statement'!F23/'Historical Financial Statement'!F19 -> 0.75607761 | G4: ='Historical Financial Statement'!G23/'Historical Financial Statement'!G19 -> 0.72942016 | H4: ='Historical Financial Statement'!H23/'Historical Financial Statement'!H19 -> 0.73550316 | I4: ='Historical Financial Statement'!I23/'Historical Financial Statement'!I19 -> 0.72348599 | J4: ='Historical Financial Statement'!J23/'Historical Financial Statement'!J19 -> 0.72935423 | ... Q4: ='Historical Financial Statement'!Q23/'Historical Financial Statement'!Q19 -> 0.73064913
B5: Interest Burden | C5: ='Historical Financial Statement'!C19/'Historical Financial Statement'!C14 -> 1.1804627 | D5: ='Historical Financial Statement'!D19/'Historical Financial Statement'!D14 -> 1.1952356 | E5: ='Historical Financial Statement'!E19/'Historical Financial Statement'!E14 -> 1.1587092 | F5: ='Historical Financial Statement'!F19/'Historical Financial Statement'!F14 -> 1.1359038 | G5: ='Historical Financial Statement'!G19/'Historical Financial Statement'!G14 -> 1.0814719 | H5: ='Historical Financial Statement'!H19/'Historical Financial Statement'!H14 -> 1.0747814 | I5: ='Historical Financial Statement'!I19/'Historical Financial Statement'!I14 -> 1.0782074 | J5: ='Historical Financial Statement'!J19/'Historical Financial Statement'!J14 -> 1.1335874 | ... Q5: ='Historical Financial Statement'!Q19/'Historical Financial Statement'!Q14 -> 1.0953679
B6: Operating Margin | C6: ='Ratios Analysis'!C6 -> 0.24678757 | D6: ='Ratios Analysis'!D6 -> 0.24047815 | E6: ='Ratios Analysis'!E6 -> 0.21964318 | F6: ='Ratios Analysis'!F6 -> 0.2133912 | G6: ='Ratios Analysis'!G6 -> 0.2450633 | H6: ='Ratios Analysis'!H6 -> 0.23030886 | I6: ='Ratios Analysis'!I6 -> 0.21057186 | J6: ='Ratios Analysis'!J6 -> 0.20659205 | ... Q6: ='Ratios Analysis'!Q6 -> 0.23170676
B7: Assets Turnover | C7: ='Ratios Analysis'!C19 -> 0.82363977 | D7: ='Ratios Analysis'!D19 -> 0.88875726 | E7: ='Ratios Analysis'!E19 -> 0.98345348 | F7: ='Ratios Analysis'!F19 -> 0.98900871 | G7: ='Ratios Analysis'!G19 -> 0.93452763 | H7: ='Ratios Analysis'!H19 -> 1.0420804 | I7: ='Ratios Analysis'!I19 -> 1.1779431 | J7: ='Ratios Analysis'!J19 -> 1.1297603 | ... Q7: ='Ratios Analysis'!Q19 -> 1.0770442
B8: Equity Multiplier | C8: ='Historical Financial Statement'!C60/SUM('Historical Financial Statement'!C29:C30) -> 1.2053579 | D8: ='Historical Financial Statement'!D60/SUM('Historical Financial Statement'!D29:D30) -> 1.2222017 | E8: ='Historical Financial Statement'!E60/SUM('Historical Financial Statement'!E29:E30) -> 1.2943586 | F8: ='Historical Financial Statement'!F60/SUM('Historical Financial Statement'!F29:F30) -> 1.4025974 | G8: ='Historical Financial Statement'!G60/SUM('Historical Financial Statement'!G29:G30) -> 1.4081152 | H8: ='Historical Financial Statement'!H60/SUM('Historical Financial Statement'!H29:H30) -> 1.5491573 | I8: ='Historical Financial Statement'!I60/SUM('Historical Financial Statement'!I29:I30) -> 1.6523134 | J8: ='Historical Financial Statement'!J60/SUM('Historical Financial Statement'!J29:J30) -> 1.543647 | ... Q8: ='Historical Financial Statement'!Q60/SUM('Historical Financial Statement'!Q29:Q30) -> 1.4790119
B10: DuPont 3 Step Model
B11: Return on Equity | C11: =C3*C7*C8 -> 0.20806877 | D11: =D3*D7*D8 -> 0.24689247 | E11: =E3*E7*E8 -> 0.23726674 | F11: =F3*F7*F8 -> 0.2542246 | G11: =G3*G7*G8 -> 0.25439091 | H11: =H3*H7*H8 -> 0.29390843 | I11: =I3*I7*I8 -> 0.31970507 | J11: =J3*J7*J8 -> 0.29788007 | ... Q11: =Q3*Q7*Q8 -> 0.29540156
B13: DuPont 5 Step Model
B14: Return on Equity | C14: =C4*C5*C6*C7*C8 -> 0.20806877 | D14: =D4*D5*D6*D7*D8 -> 0.24689247 | E14: =E4*E5*E6*E7*E8 -> 0.23726674 | F14: =F4*F5*F6*F7*F8 -> 0.2542246 | G14: =G4*G5*G6*G7*G8 -> 0.25439091 | H14: =H4*H5*H6*H7*H8 -> 0.29390843 | I14: =I4*I5*I6*I7*I8 -> 0.31970507 | J14: =J4*J5*J6*J7*J8 -> 0.29788007 | ... Q14: =Q4*Q5*Q6*Q7*Q8 -> 0.29540156

Sheet BETA Calculation
B1: ="BETA Calculation for "&'Data Sheet'!B1 -> BETA Calculation for INFOSYS LTD
B2: Infosys | F2: Nifty-500
B3: Date | C3: Price | D3: Return | F3: Price | G3: Return
B4: 10/18/2026 | C4: 1153.8 | D4: =IFERROR((C4/C5)-1,0) -> -0.0063727179 | F4: 21696.55 | G4: =IFERROR((F4/F5)-1,0) -> -0.025752075 | I4: Correlation Between Infosys and Nifty-500 | J4: =CORREL(D4:D525,G4:G525) -> 0.40394329 | K4: covariance Between Infosys And Nifty-500 | L4: =_xlfn.COVARIANCE.S(D4:D525,G4:G525) -> 0.00032215851
B5: 46336 | C5: 1161.2 | D5: =IFERROR((C5/C6)-1,0) -> 0.13464921 | F5: 22270.05 | G5: =IFERROR((F5/F6)-1,0) -> 0.018448185 | I5: Standard Deviation of Infosys | J5: =_xlfn.STDEV.S(D4:D525) -> 0.036613198 | K5: Variance of Nifty-500 | L5: =_xlfn.VAR.S(G4:G525) -> 0.00047448565
B6: 46122 | C6: 1023.4 | D6: =IFERROR((C6/C7)-1,0) -> -0.011207729 | F6: 21866.65 | G6: =IFERROR((F6/F7)-1,0) -> 0.00040717823 | I6: Standard Deviation of Nifty-500 | J6: =_xlfn.STDEV.S(G4:G525) -> 0.021782692
B7: 09/27/2026 | C7: 1035 | D7: =IFERROR((C7/C8)-1,0) -> 0.034793041 | F7: 21857.75 | G7: =IFERROR((F7/F8)-1,0) -> -0.032992678
B8: 09/20/2026 | C8: 1000.2 | D8: =IFERROR((C8/C9)-1,0) -> -0.048696975 | F8: 22603.5 | G8: =IFERROR((F8/F9)-1,0) -> -0.010378472 | I8: BETA(L) | J8: =J4*(J5/J6) -> 0.67896364
B9: 09/13/2026 | C9: 1051.4 | D9: =IFERROR((C9/C10)-1,0) -> 0.013202274 | F9: 22840.55 | G9: =IFERROR((F9/F10)-1,0) -> -0.0011348479 | I9: BETA(UL) | J9: =J8/(1+('DCF Model'!C4/'DCF Model'!C3)*(1-'DCF Model'!C9)) -> 0.67000398
B10: 46182 | C10: 1037.7 | D10: =IFERROR((C10/C11)-1,0) -> -0.081681416 | F10: 22866.5 | G10: =IFERROR((F10/F11)-1,0) -> -0.016670143
B11: 08/30/2026 | C11: 1130 | D11: =IFERROR((C11/C12)-1,0) -> -0.012237762 | F11: 23254.15 | G11: =IFERROR((F11/F12)-1,0) -> -0.011662427 | I11: BETA(L) Re-Check | J11: =L4/L5 -> 0.67896364
B12: 08/23/2026 | C12: 1144 | D12: =IFERROR((C12/C13)-1,0) -> 0.020517395 | F12: 23528.55 | G12: =IFERROR((F12/F13)-1,0) -> -7.4372192e-05
B13: 08/16/2026 | C13: 1121 | D13: =IFERROR((C13/C14)-1,0) -> -0.041224769 | F13: 23530.3 | G13: =IFERROR((F13/F14)-1,0) -> -0.0027378798
B14: 46273 | C14: 1169.2 | D14: =IFERROR((C14/C15)-1,0) -> -0.0050208493 | F14: 23594.9 | G14: =IFERROR((F14/F15)-1,0) -> -0.0049426242
B15: 46061 | C15: 1175.1 | D15: =IFERROR((C15/C16)-1,0) -> 0.039819485 | F15: 23712.1 | G15: =IFERROR((F15/F16)-1,0) -> 0.010715793
B16: 07/26/2026 | C16: 1130.1 | D16: =IFERROR((C16/C17)-1,0) -> 0.085695072 | F16: 23460.7 | G16: =IFERROR((F16/F17)-1,0) -> 0.023890055
B17: 07/19/2026 | C17: 1040.9 | D17: =IFERROR((C17/C18)-1,0) -> -0.050706794 | F17: 22913.3 | G17: =IFERROR((F17/F18)-1,0) -> -0.018126267
B18: 46363 | C18: 1096.5 | D18: =IFERROR((C18/C19)-1,0) -> 0.026685393 | F18: 23336.3 | G18: =IFERROR((F18/F19)-1,0) -> -0.0005182368
B19: 46149 | C19: 1068 | D19: =IFERROR((C19/C20)-1,0) -> 0.01986249 | F19: 23348.4 | G19: =IFERROR((F19/F20)-1,0) -> 0.0020277969
B20: 06/28/2026 | C20: 1047.2 | D20: =IFERROR((C20/C21)-1,0) -> 0.0057625816 | F20: 23301.15 | G20: =IFERROR((F20/F21)-1,0) -> 0.0081099088
B21: 06/21/2026 | C21: 1041.2 | D21: =IFERROR((C21/C22)-1,0) -> -0.0097013506 | F21: 23113.7 | G21: =IFERROR((F21/F22)-1,0) -> -0.0013178248
B22: 06/14/2026 | C22: 1051.4 | D22: =IFERROR((C22/C23)-1,0) -> -0.058222859 | F22: 23144.2 | G22: =IFERROR((F22/F23)-1,0) -> 0.024088709
B23: 46209 | C23: 1116.4 | D23: =IFERROR((C23/C24)-1,0) -> -0.067724426 | F23: 22599.8 | G23: =IFERROR((F23/F24)-1,0) -> 0.0059847721
B24: 05/31/2026 | C24: 1197.5 | D24: =IFERROR((C24/C25)-1,0) -> 0.031527263 | F24: 22465.35 | G24: =IFERROR((F24/F25)-1,0) -> -0.0084587545
B25: 05/24/2026 | C25: 1160.9 | D25: =IFERROR((C25/C26)-1,0) -> -0.011579395 | F25: 22657 | G25: =IFERROR((F25/F26)-1,0) -> 0.00025164119
B26: 05/17/2026 | C26: 1174.5 | D26: =IFERROR((C26/C27)-1,0) -> 0.049597855 | F26: 22651.3 | G26: =IFERROR((F26/F27)-1,0) -> 0.0053326173
B27: 46300 | C27: 1119 | D27: =IFERROR((C27/C28)-1,0) -> -0.05105156 | F27: 22531.15 | G27: =IFERROR((F27/F28)-1,0) -> -0.025285899
B28: 46086 | C28: 1179.2 | D28: =IFERROR((C28/C29)-1,0) -> -0.0022000338 | F28: 23115.65 | G28: =IFERROR((F28/F29)-1,0) -> 0.019049047
B29: 04/26/2026 | C29: 1181.8 | D29: =IFERROR((C29/C30)-1,0) -> 0.023557942 | F29: 22683.55 | G29: =IFERROR((F29/F30)-1,0) -> 0.0050287882
B30: 04/19/2026 | C30: 1154.6 | D30: =IFERROR((C30/C31)-1,0) -> -0.12444074 | F30: 22570.05 | G30: =IFERROR((F30/F31)-1,0) -> -0.013089543
B31: 46360 | C31: 1318.7 | D31: =IFERROR((C31/C32)-1,0) -> 0.020270793 | F31: 22869.4 | G31: =IFERROR((F31/F32)-1,0) -> 0.023388188
B32: 46146 | C32: 1292.5 | D32: =IFERROR((C32/C33)-1,0) -> -0.0063806888 | F32: 22346.75 | G32: =IFERROR((F32/F33)-1,0) -> 0.067264135
B33: 03/29/2026 | C33: 1300.8 | D33: =IFERROR((C33/C34)-1,0) -> 0.024493975 | F33: 20938.35 | G33: =IFERROR((F33/F34)-1,0) -> -0.0038915041
B34: 03/22/2026 | C34: 1269.7 | D34: =IFERROR((C34/C35)-1,0) -> 0.010988136 | F34: 21020.15 | G34: =IFERROR((F34/F35)-1,0) -> -0.014429456
B35: 03/15/2026 | C35: 1255.9 | D35: =IFERROR((C35/C36)-1,0) -> 0.0060882801 | F35: 21327.9 | G35: =IFERROR((F35/F36)-1,0) -> -0.0029591608
B36: 46237 | C36: 1248.3 | D36: =IFERROR((C36/C37)-1,0) -> -0.045933965 | F36: 21391.2 | G36: =IFERROR((F36/F37)-1,0) -> -0.048489189
B37: 46025 | C37: 1308.4 | D37: =IFERROR((C37/C38)-1,0) -> 0.0063841243 | F37: 22481.3 | G37: =IFERROR((F37/F38)-1,0) -> -0.029591852
B38: 02/22/2026 | C38: 1300.1 | D38: =IFERROR((C38/C39)-1,0) -> -0.039240319 | F38: 23166.85 | G38: =IFERROR((F38/F39)-1,0) -> -0.0097520838
B39: 02/15/2026 | C39: 1353.2 | D39: =IFERROR((C39/C40)-1,0) -> -0.011613469 | F39: 23395 | G39: =IFERROR((F39/F40)-1,0) -> 0.0035108941
B40: 46236 | C40: 1369.1 | D40: =IFERROR((C40/C41)-1,0) -> -0.091566585 | F40: 23313.15 | G40: =IFERROR((F40/F41)-1,0) -> -0.0051570368
...

Sheet Calculation
A1: * | B1: ="Calculation for "&'Data Sheet'!B1 -> Calculation for INFOSYS LTD
B2: ='Data Sheet'!A16 -> Report Date | C2: ='Data Sheet'!B16 -> 42825 | D2: ='Data Sheet'!C16 -> 43190 | E2: ='Data Sheet'!D16 -> 43555 | F2: ='Data Sheet'!E16 -> 43921 | G2: ='Data Sheet'!F16 -> 44286 | H2: ='Data Sheet'!G16 -> 44651 | I2: ='Data Sheet'!H16 -> 45016 | ... L2: ='Data Sheet'!K16 -> 46112 | M2: =L2+365 -> 46477 | N2: =M2+365 -> 46842 | O2: =N2+365 -> 47207 | P2: =O2+365 -> 47572 | Q2: =P2+365 -> 47937 | S2: 46477 | T2: 46842 | U2: 47207 | V2: 47572 | W2: 47937
B3: ='Historical Financial Statement'!B3 -> Sales | C3: ='Historical Financial Statement'!C3 -> 68484 | D3: ='Historical Financial Statement'!D3 -> 70522 | E3: ='Historical Financial Statement'!E3 -> 82675 | F3: ='Historical Financial Statement'!F3 -> 90791 | G3: ='Historical Financial Statement'!G3 -> 100472 | H3: ='Historical Financial Statement'!H3 -> 121641 | I3: ='Historical Financial Statement'!I3 -> 146767 | ... L3: ='Historical Financial Statement'!L3 -> 178650 | M3: =L3*(1+$C4) -> 196627.57 | N3: =M3*(1+$C4) -> 216414.22 | O3: =N3*(1+$C4) -> 238192.01 | P3: =O3*(1+$C4) -> 262161.3 | Q3: =P3*(1+$C4) -> 288542.62 | S3: Fixed Assets Schedule
B4: CAGR | C4: =_xlfn.RRI(10,C3,L3) -> 0.10063011 | S4: =L18 -> 33770 | T4: =S7 -> 33664.389 | U4: =T7 -> 33604.963 | V4: =U7 -> 33891.802 | W4: =V7 -> 34381.206
S5: =-M19 -> -4711.642 | T5: =-N19 -> -4763.7377 | U5: =-O19 -> -4733.8014 | V5: =-P19 -> -4813.7466 | W5: =-Q19 -> -4946.5198
B6: ='Historical Financial Statement'!B4 -> COGS | C6: ='Historical Financial Statement'!C4 -> 44609 | D6: ='Historical Financial Statement'!D4 -> 46395 | E6: ='Historical Financial Statement'!E4 -> 55446 | F6: ='Historical Financial Statement'!F4 -> 62210 | G6: ='Historical Financial Statement'!G4 -> 68490 | H6: ='Historical Financial Statement'!H4 -> 84819 | I6: ='Historical Financial Statement'!I4 -> 104880 | ... L6: ='Historical Financial Statement'!L4 -> 128257 | M6: =M3*C8 -> 135828.55 | N6: =N3*D8 -> 150349.94 | O6: =O3*E8 -> 166357.47 | P6: =P3*F8 -> 183825.99 | Q6: =Q3*G8 -> 202785.92 | S6: =M24 -> 4606.0312 | T6: =N24 -> 4704.311 | U6: =O24 -> 5020.6413 | V6: =P24 -> 5303.1497 | W6: =Q24 -> 5369.4902
B7: % COGS | C7: =C6/C3 -> 0.65137842 | D7: =D6/D3 -> 0.65787981 | E7: =E6/E3 -> 0.67065014 | F7: =F6/F3 -> 0.68520007 | G7: =G6/G3 -> 0.68168246 | H7: =H6/H3 -> 0.69728957 | I7: =I6/I3 -> 0.71460206 | J7: =J6/J3 -> 0.71601484 | ... Q7: =Q6/Q3 -> 0.70279365 | S7: =SUM(S4:S6) -> 33664.389 | T7: =SUM(T4:T6) -> 33604.963 | U7: =SUM(U4:U6) -> 33891.802 | V7: =SUM(V4:V6) -> 34381.206 | W7: =SUM(W4:W6) -> 34804.176
B8: Average | C8: =AVERAGE(C7:L7) -> 0.690791 | D8: =AVERAGE(D7:M7) -> 0.69473225 | E8: =AVERAGE(E7:N7) -> 0.6984175 | F8: =AVERAGE(F7:O7) -> 0.70119423 | G8: =AVERAGE(G7:P7) -> 0.70279365
B10: ='Historical Financial Statement'!B8 -> Selling and admin | C10: ='Historical Financial Statement'!C8 -> 4584 | D10: ='Historical Financial Statement'!D8 -> 4585 | E10: ='Historical Financial Statement'!E8 -> 5553 | F10: ='Historical Financial Statement'!F8 -> 5375 | G10: ='Historical Financial Statement'!G8 -> 3194 | H10: ='Historical Financial Statement'!H8 -> 4305 | I10: ='Historical Financial Statement'!I8 -> 5300 | ... L10: ='Historical Financial Statement'!L8 -> 6784 | M10: =M3*C12 -> 9315.4617 | N10: =N3*D12 -> 9829.5894 | O10: =O3*E12 -> 10352.007 | P10: =P3*F12 -> 10772.255 | Q10: =Q3*G12 -> 11333.667 | S10: Resevers Schedule
B11: % Selling and admin | C11: =C10/C3 -> 0.066935343 | D11: =D10/D3 -> 0.065015173 | E11: =E10/E3 -> 0.067166616 | F11: =F10/F3 -> 0.059201903 | G11: =G10/G3 -> 0.031789951 | H11: =H10/H3 -> 0.035391028 | I11: =I10/I3 -> 0.03611166 | J11: =J10/J3 -> 0.037125008 | ... Q11: =Q10/Q3 -> 0.039279006 | S11: ='Historical Financial Statement'!L30 -> 90828 | T11: =S14 -> 105689.07 | U11: =T14 -> 121516.54 | V11: =U14 -> 138075.35 | W11: =V14 -> 157662.03
B12: Average % | C12: =AVERAGE(C11:L11) -> 0.047376173 | D12: =AVERAGE(D11:M11) -> 0.045420256 | E12: =AVERAGE(E11:N11) -> 0.043460764 | F12: =AVERAGE(F11:O11) -> 0.041090179 | G12: =AVERAGE(G11:P11) -> 0.039279006 | S12: =+'Historical Financial Statement'!M23 -> 36936.321 | T12: =+'Historical Financial Statement'!N23 -> 40487.474 | U12: =+'Historical Financial Statement'!O23 -> 43971.496 | V12: =+'Historical Financial Statement'!P23 -> 48581.185 | W12: =+'Historical Financial Statement'!Q23 -> 53507.855
S13: =-M45 -> -22075.25 | T13: =-N45 -> -24660.004 | U13: =-O45 -> -27412.689 | V13: =-P45 -> -28994.5 | W13: =-Q45 -> -32057.894
B14: ='Historical Financial Statement'!B9 -> Other Expenses | C14: ='Historical Financial Statement'!C9 -> 687 | D14: ='Historical Financial Statement'!D9 -> 720 | E14: ='Historical Financial Statement'!E9 -> 1506 | F14: ='Historical Financial Statement'!F9 -> 939 | G14: ='Historical Financial Statement'!G9 -> 899 | H14: ='Historical Financial Statement'!H9 -> 1026 | I14: ='Historical Financial Statement'!I9 -> 1457 | ... L14: ='Historical Financial Statement'!L9 -> 1329 | M14: =M3*C16 -> 1972.322 | N14: =N3*D16 -> 2170.7799 | O14: =O3*E16 -> 2384.9643 | P14: =P3*F16 -> 2409.9093 | Q14: =Q3*G16 -> 2619.2373 | S14: =SUM(S11:S13) -> 105689.07 | T14: =SUM(T11:T13) -> 121516.54 | U14: =SUM(U11:U13) -> 138075.35 | V14: =SUM(V11:V13) -> 157662.03 | W14: =SUM(W11:W13) -> 179111.99
B15: % Other Expenses | C15: =C14/C3 -> 0.01003154 | D15: =D14/D3 -> 0.01020958 | E15: =E14/E3 -> 0.018215906 | F15: =F14/F3 -> 0.010342435 | G15: =G14/G3 -> 0.0089477665 | H15: =H14/H3 -> 0.0084346561 | I15: =I14/I3 -> 0.0099272997 | J15: =J14/J3 -> 0.0098262511 | ... Q15: =Q14/Q3 -> 0.009077471
B16: Average % | C16: =AVERAGE(C15:L15) -> 0.01003075 | D16: =AVERAGE(D15:M15) -> 0.010030671 | E16: =AVERAGE(E15:N15) -> 0.01001278 | F16: =AVERAGE(F15:O15) -> 0.0091924677 | G16: =AVERAGE(G15:P15) -> 0.009077471
